Workbook

Sheet SUMMARY
E2: GHANA FIXED INCOME MARKET
A3: Date: Wednesday, 05 August, 2026
A4: ITEM | D4: VOLUME | E4: NUMBER | F4: SECURITY | G4: YIELD | H4: CLOSING PRICE
A5: A | B5: GRAND TOTALS | C5: NEW GOG NOTES & BONDS | D5: ='NEW GOG NOTES AND BONDS'!H6 -> 1105000 | E5: ='NEW GOG NOTES AND BONDS'!I6 -> 3
C6: DDEP BONDS | D6: ='DDEP BONDS'!H40 -> 326610503 | E6: ='DDEP BONDS'!I40 -> 23
C7: OLD GOG NOTES & BONDS | D7: ='OLD GOG NOTES AND BONDS '!H28 -> 0 | E7: ='OLD GOG NOTES AND BONDS '!I28 -> 0
C8: TREASURY BILLS | D8: ='TREASURY BILLS'!K98 -> 671783699 | E8: ='TREASURY BILLS'!L98 -> 2576
C9: CORPORATE BONDS | D9: ='CORPORATE '!G32 -> 2200000 | E9: ='CORPORATE '!H32 -> 3
C10: SELL/BUY BACK TRADES - ALL GOG NOTES & BONDS | D10: ='SELL BUY BACK TRADES- GOG BONDS'!G44 -> 101830208 | E10: ='SELL BUY BACK TRADES- GOG BONDS'!H44 -> 14
D11: =SUM(D5:D10) -> 1103529410 | E11: =SUM(E5:E10) -> 2619
A15: B | B15: LARGEST VOLUME TRADED | C15: NEW GOG NOTES & BONDS | D15: ='NEW GOG NOTES AND BONDS'!H5 -> 1105000 | E15: ='NEW GOG NOTES AND BONDS'!I5 -> 3 | F15: ='NEW GOG NOTES AND BONDS'!C5 -> GOG-BD-29/03/33-A6155-2001-12.50 | G15: ='NEW GOG NOTES AND BONDS'!F5 -> 12.37 | H15: ='NEW GOG NOTES AND BONDS'!G5 -> 100.55284
C16: DDEP BONDS | D16: 108443336 | E16: 3 | F16: GOG-BD-10/02/32-A6148-1838-9.10 | G16: ='DDEP BONDS'!F14 -> 14.6 | H16: ='DDEP BONDS'!G14 -> 79.60052
C17: OLD GOG NOTES & BONDS
C18: TREASURY BILLS | D18: 187479417 | E18: 26 | F18: GOG-BL-01/03/27-A6984-1996-0 | G18: ='TREASURY BILLS'!J75 -> 8.3523052 | H18: ='TREASURY BILLS'!I75 -> 95.444669
C19: CORPORATE BONDS | D19: 1700000 | E19: 2 | F19: CMB-BD-28/08/28-A6301-1675-13.00
C20: SELL/BUY BACK TRADES - GOG NOTES & BONDS | D20: ='SELL BUY BACK TRADES- GOG BONDS'!G23 -> 50000000 | E20: ='SELL BUY BACK TRADES- GOG BONDS'!H23 -> 1 | F20: ='SELL BUY BACK TRADES- GOG BONDS'!C23 -> GOG-BD-03/02/37-A6153-1838-9.85 | G20: ='SELL BUY BACK TRADES- GOG BONDS'!E23 -> 14.75 | H20: ='SELL BUY BACK TRADES- GOG BONDS'!F23 -> 74.18495

Sheet NEW GOG NOTES AND BONDS
A2: GHANA FIXED INCOME MARKET
B3: =SUMMARY!A3 -> Date: Wednesday, 05 August, 2026
A4: NO. | B4: TENOR | C4: SECURITY DESCRIPTION | D4: ISIN | E4: OPENING YIELD | F4: CLOSING YIELD | G4: END OF DAY CLOSING PRICE | H4: VOLUME | I4: NUMBER TRADED | J4: DAY LOW YIELD | K4: DAY HIGH YIELD | L4: DAYS TO MATURITY | M4: MATURITY DATE | N4: APPLICABLE DATE
A5: 1 | B5: 7-YEAR BOND | C5: GOG-BD-29/03/33-A6155-2001-12.50 | D5: GHGGOGI01503 | E5: 12.2 | F5: 12.37 | G5: 100.55284 | H5: 1105000 | I5: 3 | J5: 11.847428 | K5: 12.468788 | L5: =M5-TODAY() -> 2428 | M5: 48667
C6: TOTAL | H6: =SUM(H5:H5) -> 1105000 | I6: =SUM(I5:I5) -> 3
B7: THE END OF DAY CLOSING PRICES METHODOLODY APPLIES TO GOVERNMENT NOTES, BONDS AND TREASURY BILLS
A10: NOTE
A11: 1. THE DESCRIPTION OF AN INSTRUMENT INCLUDES THE MATURITY DATE, THE ISSUE NUMBER AND THE COUPON RATE.
A12: 3. GOG-GOVERNMENT OF GHANA

Sheet DDEP BONDS
A2: GHANA FIXED INCOME MARKET
B3: =SUMMARY!A3 -> Date: Wednesday, 05 August, 2026
A4: NO. | B4: TENOR | C4: SECURITY DESCRIPTION | D4: ISIN | E4: OPENING YIELD | F4: CLOSING YIELD | G4: END OF DAY CLOSING PRICE | H4: VOLUME | I4: NUMBER TRADED | J4: DAY LOW YIELD | K4: DAY HIGH YIELD | L4: DAYS TO MATURITY | M4: MATURITY DATE | N4: APPLICABLE DATE
A5: 1 | B5: 2023-A-1 | C5: GOG-BD-17/08/27-A6139-1838-10.00 | D5: GHGGOG069873 | E5: 11.71 | F5: 11.71 | G5: 98.339123 | J5: 12.578457 | K5: 12.578457 | L5: =M5-TODAY() -> 377 | M5: 46616
A6: 2 | B6: 2023-A-2 | C6: GOG-BD-15/08/28-A6140-1838-10.00 | D6: GHGGOG069881 | E6: 12.9 | F6: 12.9 | G6: 94.720305 | J6: 14.2086 | K6: 14.2086 | L6: =M6-TODAY() -> 741 | M6: 46980
A7: 3 | B7: 2023-B-1 | C7: GOG-BD-17/08/27-A6141-1838-15.00 | D7: GHGGOG069899 | E7: 15.64 | F7: 15.64 | G7: 99.376364 | J7: 17.537546 | K7: 17.537546 | L7: =M7-TODAY() -> 377 | M7: 46616
A8: 4 | B8: 2023-B-2 | C8: GOG-BD-15/08/28-A6142-1838-15.00 | D8: GHGGOG069907 | E8: 15.58 | F8: 15.58 | G8: 98.994335 | J8: 11.893 | K8: 15 | L8: =M8-TODAY() -> 741 | M8: 46980
A9: 5 | B9: 2023-GC-1 | C9: GOG-BD-16/02/27-A6143-1838-8.35 | D9: GHGGOG069915 | E9: 10.72 | F9: 11.18 | G9: 98.556943 | H9: 56194650 | I9: 3 | J9: 10.6108 | K9: 11.5684 | L9: =M9-TODAY() -> 195 | M9: 46434
A10: 6 | B10: 2023-GC-2 | C10: GOG-BD-15/02/28-A6144-1838-8.50 | D10: GHGGOG069923 | E10: 13.59 | F10: 13.59 | G10: 93.122963 | J10: 11.007 | K10: 11.007 | L10: =M10-TODAY() -> 559 | M10: 46798
A11: 7 | B11: 2023-GC-3 | C11: GOG-BD-13/02/29-A6145-1838-8.65 | D11: GHGGOG069931 | E11: 13.37 | F11: 14 | G11: 88.890817 | H11: 15000000 | I11: 1 | J11: 12.0124 | K11: 16.0472 | L11: =M11-TODAY() -> 923 | M11: 47162
A12: 8 | B12: 2023-GC-4 | C12: GOG-BD-12/02/30-A6146-1838-8.80 | D12: GHGGOG069949 | E12: 15.06 | F12: 14.79 | G12: 83.946466 | H12: 71972517 | I12: 14 | J12: 15.02 | K12: 15.3254 | L12: =M12-TODAY() -> 1287 | M12: 47526
A13: 9 | B13: 2023-GC-5 | C13: GOG-BD-11/02/31-A6147-1838-8.95 | D13: GHGGOG069956 | E13: 14.06 | F13: 15.24 | G13: 79.923753 | H13: 75000000 | I13: 2 | J13: 13.6747 | K13: 13.6854 | L13: =M13-TODAY() -> 1651 | M13: 47890
A14: 10 | B14: 2023-GC-6 | C14: GOG-BD-10/02/32-A6148-1838-9.10 | D14: GHGGOG069964 | E14: 14.98 | F14: 14.6 | G14: 79.60052 | H14: 108443336 | I14: 3 | J14: 14.4145 | K14: 14.8656 | L14: =M14-TODAY() -> 2015 | M14: 48254
A15: 11 | B15: 2023-GC-7 | C15: GOG-BD-08/02/33-A6149-1838-9.25 | D15: GHGGOG069972 | E15: 14.65 | F15: 14.66 | G15: 77.724183 | J15: 13.761213 | K15: 13.761213 | L15: =M15-TODAY() -> 2379 | M15: 48618
A16: 12 | B16: 2023-GC-8 | C16: GOG-BD-07/02/34-A6150-1838-9.40 | D16: GHGGOG069980 | E16: 15.66 | F16: 15.27 | G16: 74.205968 | J16: 15.6193 | K16: 15.6193 | L16: =M16-TODAY() -> 2743 | M16: 48982
A17: 13 | B17: 2023-GC-9 | C17: GOG-BD-06/02/35-A6151-1838-9.55 | D17: GHGGOG069998 | E17: 15.9 | F17: 15.9 | G17: 70.822229 | J17: 16.0158 | K17: 16.0158 | L17: =M17-TODAY() -> 3107 | M17: 49346
A18: 14 | B18: 2023-GC-10 | C18: GOG-BD-05/02/36-A6152-1838-9.70 | D18: GHGGOG070004 | E18: 15.77 | F18: 15.77 | G18: 70.477391 | J18: 16.0144 | K18: 16.0144 | L18: =M18-TODAY() -> 3471 | M18: 49710
A19: 15 | B19: 2023-GC-11 | C19: GOG-BD-03/02/37-A6153-1838-9.85 | D19: GHGGOG070012 | E19: 15.55 | F19: 15.57 | G19: 70.815643 | J19: 14.758993 | K19: 14.758993 | L19: =M19-TODAY() -> 3835 | M19: 50074
A20: 16 | B20: 2023-GC-12 | C20: GOG-BD-02/02/38-A6154-1838-10.00 | D20: GHGGOG070020 | E20: 15.33 | F20: 15.44 | G20: 71.097664 | J20: 12.0053 | K20: 16.0131 | L20: =M20-TODAY() -> 4199 | M20: 50438
A24: 1 | B24: GFSF-1-4YR | C24: GOG-BD-30/11/27-A6383-1879-8.35 | D24: GHGGOG072760 | E24: 32.7567 | F24: 32.7567 | G24: 48.7154 | J24: 32.7567 | K24: 32.7567 | L24: =M24-TODAY() -> 482 | M24: 46721
A25: 2 | B25: GFSF-7-5YR | C25: GOG-BD-05/12/28-A6394-1880-8.50 | D25: GHGGOG072877 | L25: =M25-TODAY() -> 487 | M25: 46726
A26: 3 | B26: GFSF-2-6YR | C26: GOG-BD-27/11/29-A6384-1879-8.65 | D26: GHGGOG072778 | E26: 13.268768 | F26: 13.268768 | G26: 86.80886 | J26: 14.642765 | K26: 14.675197 | L26: =M26-TODAY() -> 1210 | M26: 47449
A27: 4 | B27: GFSF-8-8YR | C27: GOG-BD-02/12/31-A6396-1880-8.95 | D27: GHGGOG072893 | E27: 17.264434 | F27: 17.264434 | G27: 71.332549 | J27: 22.454135 | K27: 22.454135 | L27: =M27-TODAY() -> 1945 | M27: 48184
A28: 5 | B28: GFSF-6-10YR | C28: GOG-BD-29/11/33-A6393-1880-9.40 | D28: GHGGOG072869 | L28: =M28-TODAY() -> 2673 | M28: 48912
A29: 6 | B29: GFSF-10-11YR | C29: GOG-BD-21/11/34-A6385-1879-9.40 | D29: GHGGOG072786 | E29: 16.267711 | F29: 16.267711 | G29: 67.960057 | J29: 22.300085 | K29: 22.300085 | L29: =M29-TODAY() -> 3401 | M29: 49640
A30: 7 | B30: GFSF-9-12YR | C30: GOG-BD-27/11/35-A6395-1880-9.55 | D30: GHGGOG072885 | L30: =M30-TODAY() -> 3765 | M30: 50004
A31: 8 | B31: GFSF-4-13YR | C31: GOG-BD-25/11/36-A6391-1880-9.70 | D31: GHGGOG072844 | L31: =M31-TODAY() -> 4129 | M31: 50368
A32: 9 | B32: GFSF-5-14YR | C32: GOG-BD-24/11/37-A6392-1880-9.85 | D32: GHGGOG072851 | L32: =M32-TODAY() -> 853 | M32: 47092
A36: 1 | B36: USD-DDE-FCA-27 | C36: GOG-BD-04/09/27-A6304-1866-2.75 | D36: GHGGOG071689 | E36: 6.0215441 | F36: 6.0215441 | G36: 95.445807 | J36: 6.021544 | K36: 6.021554 | L36: =M36-TODAY() -> 395 | M36: 46634
A37: 2 | B37: USD-DDE-FCA-28 | C37: GOG-BD-04/09/28-A6305-1866-3.25 | D37: GHGGOG071697 | E37: 6.0144697 | F37: 6.0144697 | G37: 93.727908 | J37: 6.0144696 | K37: 6.014483 | L37: =M37-TODAY() -> 761 | M37: 47000
A38: 3 | B38: USD-DDE-FEA-27 | C38: GOG-BD-04/09/27-A6306-1866-2.75 | D38: GHGGOG071705 | E38: 5.2772 | F38: 5.2772 | G38: 97.3044 | J38: 4.5293 | K38: 6.0338 | L38: =M38-TODAY() -> 395 | M38: 46634
A39: 4 | B39: USD-DDE-FEA-28 | C39: GOG-BD-04/09/28-A6307-1866-3.25 | D39: GHGGOG071713 | E39: 5.7689 | F39: 5.7689 | G39: 95.0565 | J39: 5.5192 | K39: 6.0201 | L39: =M39-TODAY() -> 761 | M39: 47000
B40: TOTAL | H40: =SUM(H5:H39) -> 326610503 | I40: =SUM(I5:I39) -> 23
B41: THE END OF DAY CLOSING PRICES METHODOLODY APPLIES TO GOVERNMENT NOTES, BONDS AND TREASURY BILLS
A48: NOTE
A49: 1. THE DESCRIPTION OF AN INSTRUMENT INCLUDES THE MATURITY DATE, THE ISSUE NUMBER AND THE COUPON RATE.
A50: 2. SECURITIES COLOURED RED ARE BENCHMARK SECURITIES | B50: THE OLD GOG SECURITIES WERE EXCHANGED FOR THESE NEW ONES
A51: 3. GOG-GOVERNMENT OF GHANA

Sheet OLD GOG NOTES AND BONDS 
A2: GHANA FIXED INCOME MARKET
A3: =SUMMARY!A3 -> Date: Wednesday, 05 August, 2026
A4: NO. | B4: TENOR | C4: SECURITY DESCRIPTION | D4: ISIN | E4: OPENING YIELD | F4: CLOSING YIELD | G4: END OF DAY CLOSING PRICE | H4: VOLUME | I4: NUMBER TRADED | J4: DAY LOW YIELD | K4: DAY HIGH YIELD | L4: DAYS TO MATURITY | M4: MATURITY DATE | N4: APPLICABLE DATE
A5: 1 | B5: 5-YEAR BOND | C5: GOG-BD-26/08/26-A5701-1761-18.85 | D5: GHGGOG064247 | E5: 62.7 | F5: 62.7 | G5: 94.756847 | J5: 62.7 | K5: 62.7 | L5: =M5-TODAY() -> 21 | M5: 46260
A6: 2 | C6: GOG-BD-19/11/26-A5765-1772-6.00 | D6: GHGGOG064908 | E6: 6.6241134 | F6: 6.6241134 | G6: 99.405578 | J6: 6.6241134 | K6: 6.6241134 | L6: =M6-TODAY() -> 106 | M6: 46345
A7: 3 | C7: GOG-BD-14/12/26-A5789-1777-21.00 | D7: GHGGOG065145 | E7: 19.504721 | F7: 19.504721 | G7: 100.67331 | J7: 19.504721 | K7: 19.504721 | L7: =M7-TODAY() -> 131 | M7: 46370
A8: 4 | C8: GOG-BD-08/03/27-A5859-1789-20.75 | D8: GHGGOG065921 | E8: 30.145384 | F8: 30.145384 | G8: 91.620192 | J8: 30.145384 | K8: 30.145384 | L8: =M8-TODAY() -> 215 | M8: 46454
A9: 5 | C9: GOG-BD-03/05/27-A5904-1797-22.30 | D9: GHGGOG066424 | E9: 22.72 | F9: 22.72 | G9: 99.561038 | J9: 25.998921 | K9: 25.998921 | L9: =M9-TODAY() -> 271 | M9: 46510
A11: 1 | B11: 6-YEAR BOND | C11: GOG-BD-18/01/27-A5531-1730-19.25 | D11: GHGGOG062373 | E11: 20.65 | F11: 64.02 | G11: 83.866849 | J11: 55.71 | K11: 55.71 | L11: =M11-TODAY() -> 166 | M11: 46405
A12: 2 | C12: GOG-BD-06/09/27-A5708-1763-18.80 | D12: GHGGOG064312 | E12: 35.4463 | F12: 35.4463 | G12: 85.6798 | J12: 35.4463 | K12: 35.4463 | L12: =M12-TODAY() -> 397 | M12: 46636
A13: 3 | C13: GOG-BD-17/01/28-A5818-1782-21.75 | D13: GHGGOG065475 | E13: 22.1925 | F13: 22.1925 | G13: 99.4454 | J13: 22.1925 | K13: 22.1925 | L13: =M13-TODAY() -> 530 | M13: 46769
A15: 1 | B15: 7-YEAR BOND | C15: GOG-BD-09/08/27-A5394-1707-20.00 | D15: GHGGOG060674 | E15: 15.873336 | F15: 15.873336 | G15: 104.53499 | J15: 12.003243 | K15: 20.000071 | L15: =M15-TODAY() -> 369 | M15: 46608
A16: 2 | C16: GOG-BD-08/11/27-A5471-1720-20.50 | D16: GHGGOG061714 | E16: 24.709861 | F16: 24.709861 | G16: 94.851288 | J16: 24.447361 | K16: 25.12575 | L16: =M16-TODAY() -> 460 | M16: 46699
A17: 3 | C17: GOG-BD-12/06/28-A5638-1751-18.10 | D17: GHGGOG063546 | E17: 19.57 | F17: 19.57 | G17: 97.675171 | J17: 18.062549 | K17: 18.062549 | L17: =M17-TODAY() -> 677 | M17: 46916
A19: 1 | B19: 10-YEAR BOND | C19: GOG-BD-02/11/26-A4338-1511-19.00 | D19: GHGGOG043563 | E19: 6.9747879 | F19: 6.9747879 | G19: 105.94681 | J19: 5.9372276 | K19: 7.3578428 | L19: =M19-TODAY() -> 89 | M19: 46328 | N19: 28
A20: 2 | C20: GOG-BD-29/05/28-A4753-1593-17.50 | D20: GHGGOG050246 | E20: 55.32 | F20: 55.32 | G20: 58.678512 | J20: 17.47516 | K20: 17.47516 | L20: =M20-TODAY() -> 663 | M20: 46902 | N20: 1
A21: 3 | C21: GOG-BD-11/06/29-A5051-1647-19.80 | D21: GHGGOG055922 | E21: 21 | F21: 21 | G21: 97.41 | J21: 19.814874 | K21: 19.814874 | L21: =M21-TODAY() -> 1041 | M21: 47280 | N21: 2
A22: 4 | C22: GOG-BD-07/07/31-A5662-1755-19.75 | D22: GHGGOG063835 | E22: 19.750804 | F22: 19.750804 | G22: 99.891482 | J22: 19.750804 | K22: 19.750804 | L22: =M22-TODAY() -> 1797 | M22: 48036
A24: 1 | B24: 15-YEAR BOND | C24: GOG-BD-15/03/32-A4430-1531-19.75 | D24: GHGGOG044751 | E24: 35.582499 | F24: 35.582499 | G24: 60 | J24: 35.582499 | K24: 35.582499 | L24: =M24-TODAY() -> 2049 | M24: 48288 | N24: 43811
A25: 2 | C25: GOG-BD-10/07/34-A5078-1652-20.00 | D25: GHGGOG056458 | E25: 19.972169 | F25: 19.972169 | G25: 100 | J25: 19.972169 | K25: 19.972169 | L25: =M25-TODAY() -> 2896 | M25: 49135 | N25: 43811
A27: 1 | B27: 20-YEAR BOND | C27: GOG-BD-01/08/39-A5103-1656-20.20 | D27: GHGGOG056763 | E27: 20.197721 | F27: 20.197721 | G27: 99.889013 | J27: 20.197721 | K27: 20.197721 | L27: =M27-TODAY() -> 4744 | M27: 50983 | N27: 43811
C28: TOTAL | H28: =SUM(H5:H27) -> 0 | I28: =SUM(I5:I27) -> 0
B29: THE END OF DAY CLOSING PRICES METHODOLODY APPLIES TO GOVERNMENT NOTES, BONDS AND TREASURY BILLS
A32: NOTE
A33: 1. THE DESCRIPTION OF AN INSTRUMENT INCLUDES THE MATURITY DATE, THE ISSUE NUMBER AND THE COUPON RATE.
A34: 3. GOG-GOVERNMENT OF GHANA

Sheet CORPORATE  
B2: GHANA FIXED INCOME MARKET
C3: =SUMMARY!A3 -> Date: Wednesday, 05 August, 2026
A4: ISSUERS | B4: NO. | C4: SECURITY DESCRIPTION | D4: ISIN | E4: OPENING PRICE | F4: CLOSING PRICE | G4: VOLUME TRADED | H4: NUMBER TRADED | I4: DAY LOW YIELD | J4: DAY HIGH YIELD | K4: DAYS TO MATURITY | L4: MATURITY DATE | M4: APPLICABLE DATE
A5: LETSHEGO GHANA PLC | B5: 1 | C5: AFB-BD-15/09/26-C0705-21.00 | D5: GHCAFB064375 | E5: 85.5037 | F5: 85.5037 | I5: 85.5037 | J5: 85.5037 | K5: =L5-TODAY() -> 41 | L5: 46280
B6: 3 | C6: LGH-BD-07/10/27-C0935-22.5 | D6: GHCLGH075744 | E6: 98.4591 | F6: 98.4591 | I6: 98.4591 | J6: 98.4591 | K6: =L6-TODAY() -> 428 | L6: 46667
B7: 2 | C7: LGH-BD-13/03/28-C0896-30.25 | D7: GHCLGH073798 | K7: 672 | L7: 46825
B8: 4 | C8: LGH-BD-04/10/29-C0936 | D8: GHCLGH075751 | E8: 110.7939 | F8: 110.7939 | I8: 110.7939 | J8: 110.7939 | K8: =L8-TODAY() -> 1156 | L8: 47395
B9: 5 | C9: LGH-NT-02/04/29-C0939-20 | D9: GHCLGH077047 | E9: 105.56513 | F9: 105.56513 | I9: 105.56513 | J9: 105.56513 | K9: =L9-TODAY() -> 971 | L9: 47210
B10: 6 | C10: LGH-NT-01/04/30-C0940 | D10: GHCLGH077062 | K10: =L10-TODAY() -> 1335 | L10: 47574
A12: BAYPORT SAVINGS AND LOANS PLC | B12: 1 | C12: BFS-BD-26/06/26-C0700-21.55 | D12: GHCBFS063609 | E12: 99.8657 | F12: 99.8657 | I12: 99.8657 | J12: 99.8657 | K12: =L12-TODAY() -> -40 | L12: 46199
B13: 2 | C13: BFS-BD-19/0926-C2851 | D13: GHCBFS071974 | K13: =L13-TODAY() -> 45 | L13: 46284
B14: 3 | C14: BFS-BD-17/10/26-CO859-23.50 | D14: GHCBFS072253 | K14: =L14-TODAY() -> 73 | L14: 46312
B15: 4 | C15: BFS-BD-26/07/27-C0931-23.5 | D15: GHCBFS075165 | E15: 102.7682 | F15: 102.7682 | I15: 102.7682 | J15: 102.7682 | K15: =L15-TODAY() -> 355 | L15: 46594
B16: 5 | C16: BFS-BD-24/07/28-C0932 | D16: GHCBFS075173 | K16: =L16-TODAY() -> 719 | L16: 46958
B17: 6 | C17: BFS-BD-01/11/27-C0937-23.5 | D17: GHCBFS075934 | E17: 103.1308 | F17: 103.1308 | I17: 103.1308 | J17: 103.1308 | K17: =L17-TODAY() -> 453 | L17: 46692
B18: 7 | C18: BFS-NT-5/08/30-19 | D18: GHGBFSI00012 | E18: 99.919392 | F18: 99.919392 | I18: 99.919392 | J18: 99.919392 | L18: 47700
A20: GHANA COCOA BOARD | B20: 1 | C20: CMB-BD-31/08/26-A6303-1675-13.00 | D20: GHGCMB071672 | E20: 99.8638 | F20: 92.735314 | J20: 99.9687 | K20: 455 | L20: 46265
B21: 2 | C21: CMB-BD-30/08/27-A6302-1675-13.00 | D21: GHGCMB071664 | E21: 101.496 | F21: 101.5498 | G21: 500000 | H21: 1 | I21: 101.7746 | J21: 98.987 | K21: 766 | L21: 46629
B22: 3 | C22: CMB-BD-28/08/28-A6301-1675-13.00 | D22: GHGCMB071656 | E22: 102.1396 | F22: 102.1268 | G22: 1700000 | H22: 2 | I22: 102.1396 | J22: 102.1396 | K22: =L22-TODAY() -> 754 | L22: 46993
A24: IZWE SAVINVGS AND LOANS PLC | B24: 1 | C24: ILL-BD-10/03/27-C0692-24.25 | D24: GHCILL062793 | E24: 101.5771 | F24: 101.5771 | I24: 101.5771 | J24: 101.5771 | K24: =L24-TODAY() -> 217 | L24: 46456
B25: 2 | C25: ILL-BD-8/04/26-C0830-22.25 | D25: GHCILL070481 | E25: 99.938187 | F25: 99.938187 | I25: 99.938187 | J25: 99.938187 | K25: =L25-TODAY() -> 246 | L25: 46485
B26: 3 | C26: ILL-BD-09/04/2027-C0906-27 | D26: GHCILL074111 | K26: =L26-TODAY() -> 247 | L26: 46486
A28: KASAPREKO PLC | B28: 1 | C28: KCP-BD-29/01/27-C0878-26 | D28: GHCKCP073272 | K28: =L28-TODAY() -> 177 | L28: 46416
B29: 2 | C29: KCP-NT-12/09/28-C0933-23.50 | D29: GHCKCP075566 | E29: 99.805701 | F29: 99.805701 | I29: 99.805701 | J29: 99.805701 | K29: =L29-TODAY() -> 769 | L29: 47008
A31: QUANTUM | B31: 1 | C31: QTL-BD-02/03/28-C0188-22.25 | D31: GHCQTL048810 | E31: 40.9633 | F31: 40.9633 | I31: 40.9633 | J31: 40.9633 | K31: =L31-TODAY() -> 575 | L31: 46814 | M31: 43811
C32: TOTAL | G32: =SUM(G5:G31) -> 2200000 | H32: =SUM(H5:H31) -> 3
C33: THE END OF DAY CLOSING PRICES METHODOLODY APPLIES TO GOVERNMENT NOTES, BONDS AND TREASURY BILLS NOT CORPORATE BONDS

Sheet TREASURY BILLS
A1: GHANA FIXED INCOME MARKET TRADING RESULTS
I2: GHANA FIXED INCOME MARKET
A3: DATE: MAY 07, 2021 | D3: =SUMMARY!A3 -> Date: Wednesday, 05 August, 2026
A4: NO. | B4: TENOR | C4: TENOR | E4: SECURITY DESCRIPTION | F4: ISIN | G4: OPENING PRICE | H4: OPENING YIELD | I4: CLOSING PRICE | J4: CLOSING YIELD | K4: VOLUME TRADED | L4: NUMBER TRADED | M4: DAY LOW PRICE | N4: DAY HIGH PRICE | O4: DAYS TO MATURITY | P4: MATURITY DATE | Q4: APPLICABLE DATE
C5: 91-DAY BILL | D5: 1 | E5: GOG-BL-10/08/26-A7025-2006-0 | F5: GHGGOGI01669 | G5: 99.841529 | H5: 9.6291592 | I5: 99.866331 | J5: 9.7441549 | K5: 395963 | L5: 14 | M5: 99.8189 | N5: 99.5882 | O5: =P5-TODAY() -> 5 | P5: 46244 | Q5: =R5-TODAY() -> -46239
D6: 2 | E6: GOG-BL-17/08/26-A7030-2007-0 | F6: GHGGOGI01693 | G6: 99.687125 | H6: 8.7879821 | I6: 99.707651 | J6: 8.8939261 | K6: 1806623 | L6: 65 | M6: 100 | N6: 99.5624 | O6: =P6-TODAY() -> 12 | P6: 46251
D7: 3 | E7: GOG-BL-24/08/26-A7035-2008-0 | F7: GHGGOGI01735 | G7: 99.565261 | H7: 7.9468049 | I7: 99.581892 | J7: 8.0436972 | K7: 1146305 | L7: 18 | M7: 99.5925 | N7: 99.5786 | O7: =P7-TODAY() -> 19 | P7: 46258
D8: 4 | E8: GOG-BL-31/08/26-A7040-2009-0 | F8: GHGGOGI01792 | G8: 99.475698 | H8: 7.1056278 | I8: 99.488807 | J8: 7.1934684 | K8: 1493057 | L8: 49 | M8: 99.2583 | N8: 99.2583 | O8: =P8-TODAY() -> 26 | P8: 46265
D9: 5 | E9: GOG-BL-07/09/26-A7045-2010-0 | F9: GHGGOGI01800 | G9: 99.381528 | H9: 6.6624967 | I9: 99.400782 | J9: 6.6494033 | K9: 6259669 | L9: 144 | M9: 100 | N9: 98.5802 | O9: =P9-TODAY() -> 33 | P9: 46272
D10: 6 | E10: GOG-BL-14/09/26-A7050-2011-0 | F10: GHGGOGI01834 | G10: 99.271192 | H10: 6.5179 | I10: 99.289311 | J10: 6.5135567 | K10: 2544015 | L10: 54 | M10: 100 | N10: 98.5588 | O10: =P10-TODAY() -> 40 | P10: 46279
D11: 7 | E11: GOG-BL-21/09/26-A7055-2012-0 | F11: GHGGOGI01867 | G11: 99.166569 | H11: 6.3733033 | I11: 99.183231 | J11: 6.37771 | K11: 841845 | L11: 10 | M11: 100 | N11: 98.7842 | O11: =P11-TODAY() -> 47 | P11: 46286
D12: 8 | E12: GOG-BL-28/09/26-A7060-2013-0 | F12: GHGGOGI01891 | G12: 99.067624 | H12: 6.2287067 | I12: 99.082505 | J12: 6.2418633 | K12: 230078 | L12: 6 | M12: 100 | N12: 98.9945 | O12: =P12-TODAY() -> 54 | P12: 46293
D13: 9 | E13: GOG-BL-05/10/26-A7065-2014-0 | F13: GHGGOGI01925 | G13: 98.971409 | H13: 6.1015831 | I13: 98.985901 | J13: 6.1133419 | K13: 1185802 | L13: 32 | M13: 98.9341 | N13: 98.5064 | O13: =P13-TODAY() -> 61 | P13: 46300
D14: 10 | E14: GOG-BL-12/10/26-A7070-2015-0 | F14: GHGGOGI01958 | G14: 98.872066 | H14: 6.0181424 | I14: 98.886289 | J14: 6.0287722 | K14: 819937 | L14: 8 | M14: 100 | N14: 98.7823 | O14: =P14-TODAY() -> 68 | P14: 46307
D15: 11 | E15: GOG-BL-19/10/26-A7075-2016-0 | F15: GHGGOGI01982 | G15: 98.776053 | H15: 5.9347016 | I15: 98.790052 | J15: 5.9442024 | K15: 1174781 | L15: 29 | M15: 100 | N15: 98.2085 | O15: =P15-TODAY() -> 75 | P15: 46314
D16: 12 | E16: GOG-BL-26/10/26-A7080-2017-0 | F16: GHGGOGI02014 | G16: 98.683351 | H16: 5.8512609 | I16: 98.697171 | J16: 5.8596326 | K16: 80229718 | L16: 1727 | M16: 100 | N16: 98.0599 | O16: =P16-TODAY() -> 82 | P16: 46321
D17: 13 | E17: GOG-BL-02/11/26-A7080-2018-0 | F17: GHGGOGI02048 | G17: 98.593943 | H17: 5.7678201 | I17: 98.607626 | J17: 5.7750628 | K17: 1432549 | L17: 13 | O17: =P17-TODAY() -> 89 | P17: 46328
C19: 182-DAY BILL | D19: 1 | E19: GOG-BL-10/08/26-A6963-1993-0 | F19: GHGGOGI01206 | G19: 99.841529 | H19: 9.6291592 | I19: 99.866331 | J19: 9.7441549 | K19: 84299 | L19: 3 | M19: 99.7559 | N19: 99.7151 | O19: =P19-TODAY() -> 5 | P19: 46244
D20: 2 | E20: GOG-BL-17/08/26-A6968-1994-0 | F20: GHGGOGI01248 | G20: 99.687125 | H20: 8.7879821 | I20: 99.707651 | J20: 8.8939261 | K20: 237401 | L20: 5 | M20: 100 | N20: 100 | O20: =P20-TODAY() -> 12 | P20: 46251
D21: 3 | E21: GOG-BL-24/08/26-A6974-1995-0 | F21: GHGGOGI01289 | G21: 99.565261 | H21: 7.9468049 | I21: 99.581892 | J21: 8.0436972 | K21: 163681 | L21: 3 | M21: 100 | N21: 100 | O21: =P21-TODAY() -> 19 | P21: 46258
D22: 4 | E22: GOG-BL-31/08/26-A6979-1996-0 | F22: GHGGOGI01313 | G22: 99.475698 | H22: 7.1056278 | I22: 99.488807 | J22: 7.1934684 | K22: 286264 | L22: 9 | M22: 99.5351 | N22: 99.5351 | O22: =P22-TODAY() -> 26 | P22: 46265
D23: 5 | E23: GOG-BL-07/09/26-A6984-1997-0 | F23: GHGGOGI01347 | G23: 99.381528 | H23: 6.6624967 | I23: 99.400782 | J23: 6.6494033 | K23: 1447881 | L23: 37 | M23: 100 | N23: 99.141 | O23: =P23-TODAY() -> 33 | P23: 46272
D24: 6 | E24: GOG-BL-14/09/26-A6989-1998-0 | F24: GHGGOGI01404 | G24: 99.271192 | H24: 6.5179 | I24: 99.289311 | J24: 6.5135567 | K24: 130579 | L24: 5 | M24: 99.0236 | N24: 99.0236 | O24: =P24-TODAY() -> 40 | P24: 46279
D25: 7 | E25: GOG-BL-21/09/26-A6994-1999-0 | F25: GHGGOGI01438 | G25: 99.166569 | H25: 6.3733033 | I25: 99.183231 | J25: 6.37771 | K25: 559492 | L25: 6 | M25: 100 | N25: 98.9242 | O25: =P25-TODAY() -> 47 | P25: 46286
D26: 8 | E26: GOG-BL-28/09/26-A6999-2000-0 | F26: GHGGOGI01461 | G26: 99.067624 | H26: 6.2287067 | I26: 99.082505 | J26: 6.2418633 | K26: 20411 | L26: 4 | M26: 100 | N26: 100 | O26: =P26-TODAY() -> 54 | P26: 46293
D27: 9 | E27: GOG-BL-05/10/26-A7004-2001-0 | F27: GHGGOGI01529 | G27: 98.971409 | H27: 6.1015831 | I27: 98.985901 | J27: 6.1133419 | M27: 100 | N27: 100 | O27: =P27-TODAY() -> 61 | P27: 46300
D28: 10 | E28: GOG-BL-12/10/26-A7009-2002-0 | F28: GHGGOGI01552 | G28: 98.872066 | H28: 6.0181424 | I28: 98.886289 | J28: 6.0287722 | K28: 17167 | L28: 1 | M28: 100 | N28: 100 | O28: =P28-TODAY() -> 68 | P28: 46307
D29: 11 | E29: GOG-BL-19/10/26-A7014-2003-0 | F29: GHGGOGI01586 | G29: 98.776053 | H29: 5.9347016 | I29: 98.790052 | J29: 5.9442024 | K29: 599010 | L29: 9 | M29: 98.332 | N29: 98.332 | O29: =P29-TODAY() -> 75 | P29: 46314
D30: 12 | E30: GOG-BL-26/10/26-A7019-2004-0 | F30: GHGGOGI01610 | G30: 98.683351 | H30: 5.8512609 | I30: 98.697171 | J30: 5.8596326 | K30: 651409 | L30: 6 | M30: 100 | N30: 98.1896 | O30: =P30-TODAY() -> 82 | P30: 46321
D31: 13 | E31: GOG-BL-02/11/26-A7024-2005-0 | F31: GHGGOGI01644 | G31: 98.593943 | H31: 5.7678201 | I31: 98.607626 | J31: 5.7750628 | K31: 434683 | L31: 8 | M31: 100 | N31: 100 | O31: =P31-TODAY() -> 89 | P31: 46328
D32: 14 | E32: GOG-BL-09/11/26-A7029-2006-0 | F32: GHGGOGI01677 | G32: 98.456699 | H32: 5.8821341 | I32: 98.479448 | J32: 5.8544467 | K32: 824241 | L32: 3 | M32: 97.8845 | N32: 97.8845 | O32: =P32-TODAY() -> 96 | P32: 46335
D33: 15 | E33: GOG-BL-16/11/26-A7034-2007-0 | F33: GHGGOGI01701 | G33: 98.306486 | H33: 6.0294071 | I33: 98.330703 | J33: 5.9994121 | K33: 62157 | L33: 1 | M33: 100 | N33: 100 | O33: =P33-TODAY() -> 103 | P33: 46342
D34: 16 | E34: GOG-BL-23/11/26-A7039-2008-0 | F34: GHGGOGI01727 | G34: 98.151274 | H34: 6.1766802 | I34: 98.177032 | J34: 6.1443775 | K34: 206542 | L34: 3 | M34: 100 | N34: 96.7398 | O34: =P34-TODAY() -> 110 | P34: 46349
D35: 17 | E35: GOG-BL-30/11/26-A7044-2009-0 | F35: GHGGOGI01776 | G35: 97.991111 | H35: 6.3239533 | I35: 98.018483 | J35: 6.2893429 | K35: 7010 | L35: 3 | M35: 100 | N35: 100 | O35: =P35-TODAY() -> 117 | P35: 46356
D36: 18 | E36: GOG-BL-07/12/26-A7049-2010-0 | F36: GHGGOGI01818 | G36: 97.826049 | H36: 6.4712264 | I36: 97.855107 | J36: 6.4343082 | K36: 56321 | L36: 4 | M36: 96.6453 | N36: 96.5005 | O36: =P36-TODAY() -> 124 | P36: 46363
D37: 19 | E37: GOG-BL-14/12/26-A7054-2011-0 | F37: GHGGOGI01842 | G37: 97.65614 | H37: 6.6184995 | I37: 97.686953 | J37: 6.5792736 | K37: 402242 | L37: 6 | M37: 100 | N37: 100 | O37: =P37-TODAY() -> 131 | P37: 46370
D38: 20 | E38: GOG-BL-21/12/26-A7059-2012-0 | F38: GHGGOGI01875 | G38: 97.481437 | H38: 6.7657725 | I38: 97.514074 | J38: 6.724239 | K38: 87783 | L38: 3 | M38: 97.4756 | N38: 96.6977 | O38: =P38-TODAY() -> 138 | P38: 46377
D39: 21 | E39: GOG-BL-28/12/26-A7064-2013-0 | F39: GHGGOGI01909 | G39: 97.301996 | H39: 6.9130456 | I39: 97.336523 | J39: 6.8692044 | M39: 96.9081 | N39: 96.9081 | O39: =P39-TODAY() -> 145 | P39: 46384
D40: 22 | E40: GOG-BL-04/01/27-A7069-2014-0 | F40: GHGGOGI01933 | G40: 97.11787 | H40: 7.0603187 | I40: 97.154355 | J40: 7.0141698 | K40: 352734 | L40: 4 | M40: 100 | N40: 100 | O40: =P40-TODAY() -> 152 | P40: 46391
D41: 23 | E41: GOG-BL-11/01/27-A7074-2015-0 | F41: GHGGOGI01966 | G41: 96.929119 | H41: 7.2075918 | I41: 96.967624 | J41: 7.1591352 | K41: 275458 | L41: 4 | M41: 100 | N41: 100 | O41: =P41-TODAY() -> 159 | P41: 46398
...

Sheet SELL BUY BACK TRADES- GOG BONDS
A2: GHANA FIXED INCOME MARKET
B3: =SUMMARY!A3 -> Date: Wednesday, 05 August, 2026
A4: NO. | B4: TENOR | C4: SECURITY DESCRIPTION | D4: ISIN | E4: YIELD | F4: WEIGHTED AVERAGE CLOSING PRICES | G4: VOLUME | H4: NUMBER TRADED | I4: DAYS TO MATURITY | J4: MATURITY DATE | K4: APPLICABLE DATE
A5: NEW BONDS
A6: 1 | B6: 7-YEAR BOND | C6: GOG-BD-29/03/33-A6155-2001-12.50 | D6: GHGGOGI01503 | E6: 12.2 | F6: 101.3052 | I6: 2546 | J6: 48667
A8: DDEP
A9: 1 | B9: 2023-A-1 | C9: GOG-BD-17/08/27-A6139-1838-10.00 | D9: GHGGOG069873 | E9: 10.41 | F9: 99.594226 | G9: 298976 | H9: 3 | I9: 495 | J9: 46616
A10: 2 | B10: 2023-A-2 | C10: GOG-BD-15/08/28-A6140-1838-10.00 | D10: GHGGOG069881 | E10: 15.65 | F10: 90.454451 | G10: 966 | H10: 1 | I10: 859 | J10: 46980
A11: 3 | B11: 2023-B-1 | C11: GOG-BD-17/08/27-A6141-1838-15.00 | D11: GHGGOG069899 | E11: 16.09 | F11: 98.833614 | I11: 495 | J11: 46616
A12: 4 | B12: 2023-B-2 | C12: GOG-BD-15/08/28-A6142-1838-15.00 | D12: GHGGOG069907 | E12: 15.82 | F12: 98.508836 | I12: =J12-TODAY() -> 741 | J12: 46980
A13: 5 | B13: 2023-GC-1 | C13: GOG-BD-16/02/27-A6143-1838-8.35 | D13: GHGGOG069915 | E13: 9 | F13: 99.661167 | G13: 965300 | H13: 1 | I13: =J13-TODAY() -> 195 | J13: 46434
A14: 6 | B14: 2023-GC-2 | C14: GOG-BD-15/02/28-A6144-1838-8.50 | D14: GHGGOG069923 | E14: 11.3 | F14: 96.143287 | G14: 130000 | H14: 1 | I14: =J14-TODAY() -> 559 | J14: 46798
A15: 7 | B15: 2023-GC-3 | C15: GOG-BD-13/02/29-A6145-1838-8.65 | D15: GHGGOG069931 | E15: 12.54 | F15: 91.759368 | G15: 7268 | H15: 2 | I15: =J15-TODAY() -> 923 | J15: 47162
A16: 8 | B16: 2023-GC-4 | C16: GOG-BD-12/02/30-A6146-1838-8.80 | D16: GHGGOG069949 | E16: 13.01 | F16: 88.347936 | G16: 140641 | H16: 1 | I16: =J16-TODAY() -> 1287 | J16: 47526
A17: 9 | B17: 2023-GC-5 | C17: GOG-BD-11/02/31-A6147-1838-8.95 | D17: GHGGOG069956 | E17: 15.42 | F17: 79.107067 | I17: =J17-TODAY() -> 1651 | J17: 47890
A18: 10 | B18: 2023-GC-6 | C18: GOG-BD-10/02/32-A6148-1838-9.10 | D18: GHGGOG069964 | E18: 13.87 | F18: 81.80568 | I18: =J18-TODAY() -> 2015 | J18: 48254
A19: 11 | B19: 2023-GC-7 | C19: GOG-BD-08/02/33-A6149-1838-9.25 | D19: GHGGOG069972 | E19: 10.1 | F19: 96.015377 | I19: =J19-TODAY() -> 2379 | J19: 48618
A20: 12 | B20: 2023-GC-8 | C20: GOG-BD-07/02/34-A6150-1838-9.40 | D20: GHGGOG069980 | E20: 14.62 | F20: 76.596369 | G20: 37057 | H20: 2 | I20: =J20-TODAY() -> 2743 | J20: 48982
A21: 13 | B21: 2023-GC-9 | C21: GOG-BD-06/02/35-A6151-1838-9.55 | D21: GHGGOG069998 | E21: 14.3 | F21: 76.989759 | G21: 250000 | H21: 1 | I21: =J21-TODAY() -> 3107 | J21: 49346
A22: 14 | B22: 2023-GC-10 | C22: GOG-BD-05/02/36-A6152-1838-9.70 | D22: GHGGOG070004 | E22: 15.97 | F22: 69.6304 | I22: =J22-TODAY() -> 3471 | J22: 49710
A23: 15 | B23: 2023-GC-11 | C23: GOG-BD-03/02/37-A6153-1838-9.85 | D23: GHGGOG070012 | E23: 14.75 | F23: 74.18495 | G23: 50000000 | H23: 1 | I23: =J23-TODAY() -> 3835 | J23: 50074
A24: 16 | B24: 2023-GC-12 | C24: GOG-BD-02/02/38-A6154-1838-10.00 | D24: GHGGOG070020 | E24: 14.85 | F24: 73.585127 | G24: 50000000 | H24: 1 | I24: =J24-TODAY() -> 4199 | J24: 50438
A28: 1 | B28: GFSF-1-4YR | C28: GOG-BD-30/11/27-A6383-1879-8.35 | D28: GHGGOG072760 | I28: =J28-TODAY() -> 482 | J28: 46721
A29: 2 | B29: GFSF-7-5YR | C29: GOG-BD-05/12/28-A6394-1880-8.50 | D29: GHGGOG072877 | I29: =J29-TODAY() -> 487 | J29: 46726
A30: 3 | B30: GFSF-2-6YR | C30: GOG-BD-27/11/29-A6384-1879-8.65 | D30: GHGGOG072778 | I30: =J30-TODAY() -> 1210 | J30: 47449
A31: 4 | B31: GFSF-8-8YR | C31: GOG-BD-02/12/31-A6396-1880-8.95 | D31: GHGGOG072893 | I31: =J31-TODAY() -> 1945 | J31: 48184
A32: 5 | B32: GFSF-6-10YR | C32: GOG-BD-29/11/33-A6393-1880-9.40 | D32: GHGGOG072869 | I32: =J32-TODAY() -> 2673 | J32: 48912
A33: 6 | B33: GFSF-10-11YR | C33: GOG-BD-21/11/34-A6385-1879-9.40 | D33: GHGGOG072786 | I33: =J33-TODAY() -> 3401 | J33: 49640
A34: 7 | B34: GFSF-9-12YR | C34: GOG-BD-27/11/35-A6395-1880-9.55 | D34: GHGGOG072885 | I34: =J34-TODAY() -> 3765 | J34: 50004
A35: 8 | B35: GFSF-4-13YR | C35: GOG-BD-25/11/36-A6391-1880-9.70 | D35: GHGGOG072844 | I35: =J35-TODAY() -> 4129 | J35: 50368
A36: 9 | B36: GFSF-5-14YR | C36: GOG-BD-24/11/37-A6392-1880-9.85 | D36: GHGGOG072851 | I36: =J36-TODAY() -> 853 | J36: 47092
A40: 1 | B40: USD-DDE-FCA-27 | C40: GOG-BD-04/09/27-A6304-1866-2.75 | D40: GHGGOG071689 | I40: =J40-TODAY() -> 395 | J40: 46634
A41: 2 | B41: USD-DDE-FCA-28 | C41: GOG-BD-04/09/28-A6305-1866-3.25 | D41: GHGGOG071697 | E41: 79.96 | F41: 79.96 | I41: =J41-TODAY() -> 761 | J41: 47000
A42: 3 | B42: USD-DDE-FEA-27 | C42: GOG-BD-04/09/27-A6306-1866-2.75 | D42: GHGGOG071705 | I42: =J42-TODAY() -> 395 | J42: 46634
A43: 4 | B43: USD-DDE-FEA-28 | C43: GOG-BD-04/09/28-A6307-1866-3.25 | D43: GHGGOG071713 | E43: 86.8 | F43: 86.8 | I43: =J43-TODAY() -> 761 | J43: 47000
B44: TOTAL | G44: =SUM(G5:G43) -> 101830208 | H44: =SUM(H5:H43) -> 14
A47: NOTE
A48: 1. THE DESCRIPTION OF AN INSTRUMENT INCLUDES THE MATURITY DATE, THE ISSUE NUMBER AND THE COUPON RATE.
A49: 2. SECURITIES COLOURED RED ARE BENCHMARK SECURITIES | B49: THE OLD GOG SECURITIES WERE EXCHANGED FOR THESE NEW ONES
A50: 3. GOG-GOVERNMENT OF GHANA
